Workbook
Name CV: 參數!$B$4
Name SL_Z_Table: [1]參數!$D$2:$F$6
Name W: 參數!$B$2
Name ZTable: 參數!$D$2:$F$5

Sheet 整合資料
A1: 物料編號 | B1: 品名 | C1: 2023年5月 | D1: 2023年6月 | E1: 2023年7月 | F1: 2023年8月 | G1: 2023年9月 | H1: 2023年10月 | I1: 2023年11月 | J1: 2023年12月 | K1: 2024年1月 | L1: 2024年2月 | M1: 2024年3月 | N1: 2024年4月 | O1: 2024年5月 | P1: 2024年6月 | Q1: 2024年7月 | R1: 2024年8月 | S1: 2024年9月 | T1: 2024年10月 | U1: 2024年11月 | V1: 2024年12月 | W1: 2025年1月 | X1: 2025年2月 | Y1: 2025年3月 | Z1: 2025年4月 | AA1: 2025年5月 | AB1: 2025年6月 | AC1: 2025年7月 | AD1: 2025年8月 | AE1: 2025年9月 | AF1: 2025年10月 | AG1: 2025年11月 | AH1: 2025年12月 | AI1: 2023年使用量(U23) | AJ1: 2024年使用量(U24) | AK1: 2025年使用量(U25) | AL1: 南機廠庫存量 | AM1: 新北捷_請購點 | AN1: 新北捷_庫存單位 | AO1: 交貨期(L) | AP1: 採購前置時間(P) | AQ1: 安全等級 | AR1: 2023請購點(ROP) | AS1: 2024請購點(ROP) | AT1: 2025請購點(ROP)
A2: 93.14.0001.LO | B2: 電動起子馬達碳刷/廠牌：BOSCH，型號：2609199169 | H2: 2 | AI2: =SUM(C2:J2) -> 2 | AJ2: =SUM(K2:V2) -> 0 | AK2: =SUM(W2:AH2) -> 0 | AL2: 0 | AN2: 件 | AP2: 30 | AQ2: 2 | AR2: 1 | AS2: 0 | AT2: 0
A3: 94.01.0002.AF | B3: 油漆筆(白)/白色 | D3: 33 | P3: 10 | AB3: 10 | AI3: =SUM(C3:J3) -> 33 | AJ3: =SUM(K3:V3) -> 10 | AK3: =SUM(W3:AH3) -> 10 | AL3: 990 | AN3: PC | AP3: 30 | AQ3: 3 | AR3: 6 | AS3: 2 | AT3: 2
A4: 94.01.0003.AF | B4: 油漆筆(黃)/黃色 | D4: 18 | AI4: =SUM(C4:J4) -> 18 | AJ4: =SUM(K4:V4) -> 0 | AK4: =SUM(W4:AH4) -> 0 | AL4: 32 | AM4: 1 | AN4: PC | AP4: 30 | AQ4: 3 | AR4: 4 | AS4: 0 | AT4: 0
A5: 94.01.0007.AF | B5: 噴漆(白)/1.顏色: 白色 2.容量:400ml/罐(含)以上/CN | D5: 17 | AI5: =SUM(C5:J5) -> 17 | AJ5: =SUM(K5:V5) -> 0 | AK5: =SUM(W5:AH5) -> 0 | AL5: 57 | AM5: 1 | AN5: CN | AP5: 30 | AQ5: 3 | AR5: 3 | AS5: 0 | AT5: 0
A6: 94.01.0009.AF | B6: 噴漆(黑)/1.顏色: 黑色 2.容量:400ml/罐(含)以上/CN | D6: 8 | AI6: =SUM(C6:J6) -> 8 | AJ6: =SUM(K6:V6) -> 0 | AK6: =SUM(W6:AH6) -> 0 | AL6: 67 | AM6: 1 | AN6: CN | AP6: 30 | AQ6: 3 | AR6: 2 | AS6: 0 | AT6: 0
A7: 94.01.0014.LO | B7: 冷鍍鋅漆/13oz/CN，噴霧式，產品標示之保存期限：自製造日起至少 36 個月 | D7: 5 | U7: 1 | AF7: 2 | AI7: =SUM(C7:J7) -> 5 | AJ7: =SUM(K7:V7) -> 1 | AK7: =SUM(W7:AH7) -> 2 | AL7: 40 | AM7: 0 | AN7: CN | AP7: 30 | AQ7: 2 | AR7: 1 | AS7: 1 | AT7: 1
A8: 94.02.0001.LO | B8: 蒸餾水/1.適用電瓶加水用，不含金屬導電物 2.包裝方式：5GAL/桶 | L8: 5 | P8: 16 | Q8: 5 | V8: 6 | X8: 5 | AB8: 16 | AI8: =SUM(C8:J8) -> 0 | AJ8: =SUM(K8:V8) -> 32 | AK8: =SUM(W8:AH8) -> 21 | AL8: 72 | AM8: 0 | AN8: PL | AP8: 30 | AQ8: 2 | AR8: 0 | AS8: 6 | AT8: 4
A9: 94.03.0006.LO | B9: 木柄銅絲刷/植毛寬度:20mm±3mm，植毛長度:75mm±5mm，毛長:15mm±3mm，總長220mm以上 | D9: 15 | AG9: 20 | AI9: =SUM(C9:J9) -> 15 | AJ9: =SUM(K9:V9) -> 0 | AK9: =SUM(W9:AH9) -> 20 | AL9: 94 | AM9: 0 | AN9: EA | AP9: 30 | AQ9: 2 | AR9: 3 | AS9: 0 | AT9: 4
A10: 94.07.0010.LO | B10: 氬氣/充填壓力120kg/c㎡以上，容積6立方米 | H10: 1 | AI10: =SUM(C10:J10) -> 1 | AJ10: =SUM(K10:V10) -> 0 | AK10: =SUM(W10:AH10) -> 0 | AL10: 0 | AN10: PL | AP10: 30 | AQ10: 2 | AR10: 1 | AS10: 0 | AT10: 0
A11: 94.07.0017.LO | B11: 氮氣(含瓶身)/1.充填壓力：190kg/c㎡以上，水容積：50L，容積：10立方米。 2.適用氣體名稱：氮氣。 3.接頭型式：CGA580。 4.須含鋼瓶身。 | S11: 1 | U11: 1 | V11: 1 | AE11: 1 | AF11: 2 | AH11: 6 | AI11: =SUM(C11:J11) -> 0 | AJ11: =SUM(K11:V11) -> 3 | AK11: =SUM(W11:AH11) -> 9 | AL11: 3 | AM11: 0 | AN11: PL | AP11: 30 | AQ11: 2 | AR11: 0 | AS11: 1 | AT11: 2
A12: 94.12.0001.LO | B12: PVC絕緣膠布(紅色)/紅色 0.2mm*19mm*10m | J12: 2 | O12: 2 | R12: 1 | S12: 2 | AA12: 2 | AD12: 1 | AE12: 2 | AI12: =SUM(C12:J12) -> 2 | AJ12: =SUM(K12:V12) -> 5 | AK12: =SUM(W12:AH12) -> 5 | AL12: 0 | AN12: RL | AP12: 30 | AQ12: 2 | AR12: 1 | AS12: 1 | AT12: 1
A13: 94.12.0002.LO | B13: PVC絕緣膠布(黑色)/黑色 0.2mm*19mm 10m | J13: 2 | O13: 3 | R13: 1 | S13: 5 | AA13: 3 | AD13: 1 | AE13: 5 | AI13: =SUM(C13:J13) -> 2 | AJ13: =SUM(K13:V13) -> 9 | AK13: =SUM(W13:AH13) -> 9 | AL13: 0 | AN13: RL | AP13: 30 | AQ13: 2 | AR13: 1 | AS13: 2 | AT13: 2
A14: 94.12.0003.LO | B14: PVC絕緣膠布(黃色)/黃色 0.2mm*19mm*10m | J14: 1 | O14: 1 | AA14: 1 | AI14: =SUM(C14:J14) -> 1 | AJ14: =SUM(K14:V14) -> 1 | AK14: =SUM(W14:AH14) -> 1 | AL14: 0 | AN14: RL | AP14: 30 | AQ14: 2 | AR14: 1 | AS14: 1 | AT14: 1
A15: 94.12.0004.LO | B15: PVC絕緣膠布(白色)/白色 0.2mm*19mm*10m | J15: 2 | O15: 2 | S15: 2 | AA15: 2 | AE15: 2 | AI15: =SUM(C15:J15) -> 2 | AJ15: =SUM(K15:V15) -> 4 | AK15: =SUM(W15:AH15) -> 4 | AL15: 0 | AN15: RL | AP15: 30 | AQ15: 2 | AR15: 1 | AS15: 1 | AT15: 1
A16: 94.12.0005.LO | B16: PVC絕緣膠布(綠色)/綠色 0.2mm*19mm*10m | J16: 2 | O16: 2 | AA16: 2 | AI16: =SUM(C16:J16) -> 2 | AJ16: =SUM(K16:V16) -> 2 | AK16: =SUM(W16:AH16) -> 2 | AL16: 0 | AN16: RL | AP16: 30 | AQ16: 2 | AR16: 1 | AS16: 1 | AT16: 1
A17: 94.14.0007.LO | B17: 止洩帶/一般管路防漏用，規格：厚度：0.1mm、寬度：13mm、每捲長度：15m以上 | J17: 2 | M17: 5 | R17: 6 | Y17: 5 | AD17: 6 | AF17: 5 | AI17: =SUM(C17:J17) -> 2 | AJ17: =SUM(K17:V17) -> 11 | AK17: =SUM(W17:AH17) -> 16 | AL17: 30 | AM17: 0 | AN17: RL | AP17: 30 | AQ17: 2 | AR17: 1 | AS17: 2 | AT17: 3
A18: 94.14.0008.LO | B18: 矽利康(施敏打硬，黑)/1、廠牌：CEMEDINE ，型號：SUPER X NO.8008，容量:333ml/條，顏色：黑。 2、保存期限：自製造日起至少12個月。 | M18: 1 | Q18: 4 | Y18: 1 | AI18: =SUM(C18:J18) -> 0 | AJ18: =SUM(K18:V18) -> 5 | AK18: =SUM(W18:AH18) -> 1 | AL18: 48 | AM18: 0 | AN18: EA | AP18: 30 | AQ18: 2 | AR18: 0 | AS18: 1 | AT18: 1
A19: 94.14.0009.LO | B19: 熱縮套管(10.4mm)/1、廠牌：KSS，型號：F32-10 。 2、尺寸：收縮前內徑10.4mm±0.4mm。 3、內徑收縮率50%以上。 4、顏色：黑色。 5、包裝：50m/捲。 | R19: 1 | AD19: 1 | AF19: 1 | AI19: =SUM(C19:J19) -> 0 | AJ19: =SUM(K19:V19) -> 1 | AK19: =SUM(W19:AH19) -> 2 | AL19: 4 | AM19: 0 | AN19: RL | AP19: 30 | AQ19: 2 | AR19: 0 | AS19: 1 | AT19: 1
A20: 94.14.0010.LO | B20: 熱縮套管(3.5mm)/1、廠牌：KSS，型號：F32-3。 2、尺寸：收縮前內徑3.5mm±0.3mm。 3、內徑收縮率50%以上。 4、顏色：黑色。 5、包裝：200m/捲。 | R20: 1 | AD20: 1 | AF20: 1 | AI20: =SUM(C20:J20) -> 0 | AJ20: =SUM(K20:V20) -> 1 | AK20: =SUM(W20:AH20) -> 2 | AL20: 4 | AM20: 0 | AN20: RL | AP20: 30 | AQ20: 2 | AR20: 0 | AS20: 1 | AT20: 1
A21: 94.14.0011.LO | B21: PVC絕緣膠布(藍色)/藍色 0.2mm*19mm*10m。 | S21: 2 | AE21: 2 | AI21: =SUM(C21:J21) -> 0 | AJ21: =SUM(K21:V21) -> 2 | AK21: =SUM(W21:AH21) -> 2 | AL21: 0 | AM21: 0 | AN21: EA | AP21: 30 | AQ21: 2 | AR21: 0 | AS21: 1 | AT21: 1
A22: 94.16.0011.LO | B22: 凡士林(潤滑用)/容量:1kg/瓶 | D22: 2 | AI22: =SUM(C22:J22) -> 2 | AJ22: =SUM(K22:V22) -> 0 | AK22: =SUM(W22:AH22) -> 0 | AL22: 15 | AM22: 0 | AN22: CN | AP22: 30 | AQ22: 2 | AR22: 1 | AS22: 0 | AT22: 0
A23: 94.16.0013.LO | B23: 液壓油(SHELL TELLUS S2 MX 46)/1.廠牌：SHELL、型號：TELLUS S2 MX 46。2.包裝方式：209公升/桶。3.產品標示之保存期限：自製造日起至少48 個月。 | E23: 4 | N23: 1 | Q23: 3 | Z23: 1 | AC23: 4 | AI23: =SUM(C23:J23) -> 4 | AJ23: =SUM(K23:V23) -> 4 | AK23: =SUM(W23:AH23) -> 5 | AL23: 1 | AM23: 0 | AN23: PL | AP23: 30 | AQ23: 2 | AR23: 1 | AS23: 1 | AT23: 1
A24: 94.16.0015.LO | B24: 除銹潤滑油/具有滲透除銹、潤滑鎖頭、消除因機械磨擦產生雜聲等功能，可作為各類金屬或一般材質零組件的維修保養使用，包裝方式：380ml以上，產品標示之保存期限：自製造日起至少 24 個月 | D24: 84 | AF24: 5 | AG24: 5 | AH24: 5 | AI24: =SUM(C24:J24) -> 84 | AJ24: =SUM(K24:V24) -> 0 | AK24: =SUM(W24:AH24) -> 15 | AL24: 62 | AM24: 0 | AN24: CN | AP24: 30 | AQ24: 2 | AR24: 15 | AS24: 0 | AT24: 3
A25: 94.17.0001.LO | B25: 扭力標示劑/1.容量:1 o.z 2.用途:用於螺絲、螺帽鎖固後標示使用 3.顏色:螢光粉紅或橘色 4.產品標示之保存期限：自製造日起至少24個月。 | D25: 153 | AI25: =SUM(C25:J25) -> 153 | AJ25: =SUM(K25:V25) -> 0 | AK25: =SUM(W25:AH25) -> 0 | AL25: 39 | AM25: 0 | AN25: EA | AP25: 30 | AQ25: 2 | AR25: 27 | AS25: 0 | AT25: 0
A26: 94.17.0004.LO | B26: 油漆筆(綠色)/(1)廠牌：雪人牌 (2)顏色：綠色 (3)筆頭寬度：1.5~3mm (4)筆頭材質：壓克力 (5)須適用於鐵板、金屬、玻璃、塑膠、紙類、皮革、布類等材質，畫記後經擦拭，不褪色、脫漆 (6)產品標示之保存期限：自製造日起至少30個月 | D26: 12 | AI26: =SUM(C26:J26) -> 12 | AJ26: =SUM(K26:V26) -> 0 | AK26: =SUM(W26:AH26) -> 0 | AL26: 0 | AN26: PC | AP26: 30 | AQ26: 3 | AR26: 3 | AS26: 0 | AT26: 0
A27: 94.18.0003.LO | B27: 防銹潤滑油/1、廠牌：LOCTITE，型號：8023。2、容量：1LB/罐(或16盎司/罐)。3、產品標示之保存期限：自製造日起至少 60 個月。 | F27: 3 | H27: 2 | M27: 2 | O27: 2 | P27: 6 | S27: 4 | T27: 4 | U27: 1 | Y27: 2 | AA27: 2 | AB27: 6 | AE27: 4 | AI27: =SUM(C27:J27) -> 5 | AJ27: =SUM(K27:V27) -> 19 | AK27: =SUM(W27:AH27) -> 14 | AL27: 13 | AM27: 0 | AN27: CN | AP27: 30 | AQ27: 2 | AR27: 1 | AS27: 4 | AT27: 3
A28: 94.18.0007.LO | B28: 螺絲膠243/1、廠牌：LOCTITE。 2、型號：243。 3、包裝方式：50ml/罐。 4、產品標示之保存期限：自製造日起至少18個月。 | P28: 3 | S28: 4 | T28: 4 | U28: 2 | AB28: 3 | AE28: 4 | AF28: 5 | AG28: 5 | AI28: =SUM(C28:J28) -> 0 | AJ28: =SUM(K28:V28) -> 13 | AK28: =SUM(W28:AH28) -> 17 | AL28: 35 | AM28: 0 | AN28: CN | AP28: 30 | AQ28: 2 | AR28: 0 | AS28: 3 | AT28: 3
A29: 94.18.0008.LO | B29: 防卡劑/1、廠牌：LOCTITE。 2、型號：767或LB8150。 3、包裝方式：1LB/罐。 4、產品標示之保存期限：自製造日起至少36個月。 | P29: 2 | T29: 1 | U29: 2 | AB29: 2 | AI29: =SUM(C29:J29) -> 0 | AJ29: =SUM(K29:V29) -> 5 | AK29: =SUM(W29:AH29) -> 2 | AL29: 6 | AM29: 0 | AN29: CN | AP29: 30 | AQ29: 2 | AR29: 0 | AS29: 1 | AT29: 1
A30: 94.20.0003.AF | B30: 警示膠帶/48mmx25M PVC黑黃 | D30: 35 | R30: 1 | AD30: 1 | AI30: =SUM(C30:J30) -> 35 | AJ30: =SUM(K30:V30) -> 1 | AK30: =SUM(W30:AH30) -> 1 | AL30: 4 | AM30: 1 | AN30: CL | AP30: 30 | AQ30: 2 | AR30: 7 | AS30: 1 | AT30: 1
A31: 94.20.0005.AF | B31: 棉紗手套/20兩 | L31: 30 | P31: 20 | R31: 2 | V31: 5 | X31: 30 | AB31: 20 | AD31: 2 | AI31: =SUM(C31:J31) -> 0 | AJ31: =SUM(K31:V31) -> 57 | AK31: =SUM(W31:AH31) -> 52 | AL31: 846 | AM31: 1 | AN31: BL | AP31: 30 | AQ31: 2 | AR31: 0 | AS31: 10 | AT31: 10
A32: 94.22.0003.LO | B32: 瓦楞紙板/厚:3mm以上,長:180cm以上,寬:138cm以上;材質:3層瓦楞紙板 | O32: 10 | AA32: 10 | AI32: =SUM(C32:J32) -> 0 | AJ32: =SUM(K32:V32) -> 10 | AK32: =SUM(W32:AH32) -> 10 | AL32: 383 | AM32: 0 | AN32: EA | AP32: 30 | AQ32: 4 | AR32: 0 | AS32: 2 | AT32: 2
A33: 94.22.0004.LO | B33: 工業用伸縮膜/17ux50cmx500m | R33: 1 | S33: 6 | AD33: 1 | AE33: 6 | AI33: =SUM(C33:J33) -> 0 | AJ33: =SUM(K33:V33) -> 7 | AK33: =SUM(W33:AH33) -> 7 | AL33: 1 | AM33: 0 | AN33: 支 | AP33: 30 | AQ33: 4 | AR33: 0 | AS33: 2 | AT33: 2
A34: 94.22.0005.LO | B34: 夾鏈袋(由任袋)8號/1.市售規格8號 24*17cm 。 2.每包100只入。 | R34: 2 | AD34: 2 | AF34: 1 | AI34: =SUM(C34:J34) -> 0 | AJ34: =SUM(K34:V34) -> 2 | AK34: =SUM(W34:AH34) -> 3 | AL34: 1 | AM34: 0 | AN34: PG | AP34: 30 | AQ34: 4 | AR34: 0 | AS34: 1 | AT34: 1
A35: 94.22.0006.LO | B35: 夾鏈袋(由任袋)6號/1.市售規格6號 12*17cm。 2.每包100只入。 | R35: 2 | AD35: 2 | AI35: =SUM(C35:J35) -> 0 | AJ35: =SUM(K35:V35) -> 2 | AK35: =SUM(W35:AH35) -> 2 | AL35: 2 | AM35: 0 | AN35: PG | AP35: 30 | AQ35: 4 | AR35: 0 | AS35: 1 | AT35: 1
A36: 94.22.0007.LO | B36: 夾鏈袋(由任袋)10號/1.市售規格10號 34*24cm。 2.每包100只入。 | R36: 1 | AD36: 1 | AF36: 1 | AI36: =SUM(C36:J36) -> 0 | AJ36: =SUM(K36:V36) -> 1 | AK36: =SUM(W36:AH36) -> 2 | AL36: 2 | AM36: 0 | AN36: PG | AP36: 30 | AQ36: 4 | AR36: 0 | AS36: 1 | AT36: 1
A37: 94.22.0008.LO | B37: 夾鏈袋(由任袋)12號/1.市售規格12號 34*45cm。 2.每包100只入。 | R37: 1 | AD37: 1 | AI37: =SUM(C37:J37) -> 0 | AJ37: =SUM(K37:V37) -> 1 | AK37: =SUM(W37:AH37) -> 1 | AL37: 2 | AM37: 0 | AN37: PG | AP37: 30 | AQ37: 4 | AR37: 0 | AS37: 1 | AT37: 1
A38: 94.23.0011.AF | B38: 洗手粉/約3.5kg/盒 | E38: 34 | L38: 20 | P38: 10 | U38: 10 | X38: 20 | AB38: 10 | AC38: 15 | AF38: 20 | AH38: 15 | AI38: =SUM(C38:J38) -> 34 | AJ38: =SUM(K38:V38) -> 40 | AK38: =SUM(W38:AH38) -> 80 | AL38: 37 | AM38: 1 | AN38: BX | AP38: 30 | AQ38: 3 | AR38: 6 | AS38: 7 | AT38: 14
A39: 94.23.0026.LO | B39: 太空包沙袋/1.長100cm(±10cm)*寬100cm(±10cm)*高110cm(±10cm) 2.負載重量至少1噸 3.需有4個吊耳以供吊運,內部不需內裹,開口全開 4.材質使用聚丙烯或精對苯二甲酸。 | E39: 10 | F39: 15 | Q39: 21 | AH39: 30 | AI39: =SUM(C39:J39) -> 25 | AJ39: =SUM(K39:V39) -> 21 | AK39: =SUM(W39:AH39) -> 30 | AL39: 3 | AM39: 0 | AN39: EA | AP39: 30 | AQ39: 2 | AR39: 5 | AS39: 4 | AT39: 6
A40: 94.23.0028.LO | B40: 抹布/長：35~55cm，寬：35~55cm，顏色：白色，具吸水性，包裝方式：5kg/包 | D40: 270 | L40: 20 | P40: 43 | R40: 3 | S40: 3 | T40: 3 | U40: 20 | V40: 6 | X40: 20 | AB40: 43 | AC40: 4 | AD40: 3 | AE40: 3 | AF40: 10 | AH40: 23 | AI40: =SUM(C40:J40) -> 270 | AJ40: =SUM(K40:V40) -> 98 | AK40: =SUM(W40:AH40) -> 106 | AL40: 165 | AM40: 0 | AN40: PG | AP40: 30 | AQ40: 3 | AR40: 48 | AS40: 18 | AT40: 19
...

Sheet 所有料件
A1: 屬性 | B1: 料號 | C1: 品名 | D1: 品級 | E1: 規格 | F1: 單位 | G1: 倉庫 | H1: 儲位 | I1: 庫存量 | J1: 保存日期
A2: 不可修件 | B2: YA.II.0041.LO | C2: 風扇軸承 | D2: X 工程廠商依契約提供之備品 | E2: 廠牌:ASAHI 型號:UCP 207 | F2: EA | G2: 環狀線南機廠主倉庫 | H2: YSC.02.16.E.01 | I2: 10
A3: 不可修件 | B3: 50.KL.0001.AI | C3: 車廂地板 | D3: X 工程廠商依契約提供之備品 | E3: 1025 x 1470 x 17 mm | F3: PC | G3: 淡海輕軌分存站 | H3: DTS0009 | I3: 2
A4: 不可修件 | B4: 39.26.0006.CC | C4: 亂流調整板 | D4: X 工程廠商依契約提供之備品 | E4: 噴漆室適用 | F4: PC | G4: 淡海輕軌中心倉庫 | H4: DMW1132 | I4: 1
A5: 時限品 | B5: Y4.33.0011.LO | C5: 濕式螢光磁粉液 | D5: X 工程廠商依契約提供之備品 | E5: 廠牌：MAGNAFLUX，型號：14AM，包裝方式：300公克/罐，產品標示之保存期限：自製造日起至少60個月。 | F5: CN | G5: 環狀線南機廠特殊品倉庫 | H5: YSK.03.01.B.01.09.T | I5: 0 | J5: 2025/02/28
A6: 代管捷運局之工具/儀器 | B6: 96.11.0030.KL | C6: 鋼尺(300mm) | D6: X 工程廠商依契約提供之備品 | E6: 300mm | F6: ST | G6: 淡海輕軌電子零件倉 | H6: DE0211 | I6: 0
A7: 代管捷運局之工具/儀器 | B7: 96.11.0030.KL | C7: 鋼尺(300mm) | D7: X 工程廠商依契約提供之備品 | E7: 300mm | F7: ST | G7: 淡海輕軌電子零件倉 | H7: DME0213 | I7: 1
A8: 代管捷運局之工具/儀器 | B8: 96.11.0030.KL | C8: 鋼尺(300mm) | D8: X 工程廠商依契約提供之備品 | E8: 300mm | F8: ST | G8: 淡海輕軌電子零件倉 | H8: DME0211 | I8: 0
A9: 代管捷運局之工具/儀器 | B9: 96.11.0030.KL | C9: 鋼尺(300mm) | D9: X 工程廠商依契約提供之備品 | E9: 300mm | F9: ST | G9: 安坑輕軌電子零件倉 | H9: AME0104 | I9: 0
A10: 代管捷運局之工具/儀器 | B10: 96.11.0030.KL | C10: 鋼尺(300mm) | D10: X 工程廠商依契約提供之備品 | E10: 300mm | F10: ST | G10: 安坑輕軌中心倉庫 | H10: AMW4218 | I10: 0
A11: 代管捷運局之工具/儀器 | B11: 96.11.0030.KL | C11: 鋼尺(300mm) | D11: X 工程廠商依契約提供之備品 | E11: 300mm | F11: ST | G11: 安坑輕軌分存站 | H11: ATS0001 | I11: 0
A12: 代管捷運局之工具/儀器 | B12: 96.11.0030.KL | C12: 鋼尺(300mm) | D12: X 工程廠商依契約提供之備品 | E12: 300mm | F12: ST | G12: 安坑輕軌危險物品倉庫 | H12: AHS0000 | I12: 0
A13: 不可修件 | B13: Y2.PD.0202.LO | C13: JET I UV 貼膜玻璃彩繪(C2-7) | D13: X 工程廠商依契約提供之備品 | E13: 廠牌：艾瓦奇有限公司 規格：101.4cm*83.2cm 說明:板橋站月台滑門-C2-7 | F13: PC | G13: 環狀線南機廠空調倉庫 | H13: YSAC1.08.03.C | I13: 3
A14: 不可修件 | B14: 39.27.0002.CS | C14: 高壓水封組 | D14: X 工程廠商依契約提供之備品 | E14: 高壓清洗泵適用 | F14: PC | G14: 淡海輕軌中心倉庫 | H14: DMW1321 | I14: 1
A15: 不可修件 | B15: Y2.PD.0003.FA | C15: 驅動螺桿總成 | D15: X 工程廠商依契約提供之備品 | E15: 1.廠牌:Faiveley Transport，型號:Z104217-0101。 2.驅動螺桿是驅動機構組件之一部分，螺桿一半長度為右旋螺紋，另一半為左旋螺紋。 3.其功能為帶動自動滑門門扇進行開關門，使用於環狀線Faiveley月臺門系統。 | F15: EA | G15: 環狀線南機廠大型物料倉庫 | H15: YSD.G.01 | I15: 5
A16: 不可修件 | B16: Y1.EE.0022.AS | C16: 電路板(SSRB2) | D16: X 工程廠商依契約提供之備品 | E16: 廠牌:Ansaldo STS或廠牌:Hitachi Rail STS，型號：TA5A.0100001 | F16: EA | G16: 環狀線南機廠空調倉庫 | H16: YSAC1.02.04.C | I16: 1
A17: 不可修件 | B17: Y1.AA.0009.HI | C17: 局部控制單元機架1(LCU) | D17: X 工程廠商依契約提供之備品 | E17: 廠牌：HRI，型號：008974TE03 | F17: EA | G17: 環狀線南機廠主倉庫 | H17: YSC.03.11.B.01 | I17: 2
... A113: 不可修件 | B113: 39.29.0029.GM | C113: 保險絲 7,5 A | D113: X 工程廠商依契約提供之備品 | E113: 電氣系統適用 | F113: PC | G113: 安坑輕軌中心倉庫 | H113: AMW1422 | I113: 10
A114: 時限品 | B114: YA.HH.0012.LO | C114: 皮帶(SPZ-1800) | D114: X 工程廠商依契約提供之備品 | E114: 廠牌:科祿格規格:SPZ-1800 | F114: EA | G114: 環狀線南機廠主倉庫 | H114: YSC.03.09.A.03.11.T | I114: 0 | J114: 2024/01/10
A115: 不可修件 | B115: Y2.PD.0209.LO | C115: 3M長期UV全透明彩繪PVC-月台滑門(右) | D115: N 採購品 | E115: 廠牌：爵士影像事業有限公司 規格：103cm*208cm 說明:月台滑門(右) | F115: PC | G115: 環狀線南機廠大型物料倉庫 | H115: YSD.G | I115: 0
A116: 不可修件 | B116: Y2.PD.0209.LO | C116: 3M長期UV全透明彩繪PVC-月台滑門(右) | D116: N 採購品 | E116: 廠牌：爵士影像事業有限公司 規格：103cm*208cm 說明:月台滑門(右) | F116: PC | G116: 環狀線南機廠空調倉庫 | H116: YSAC1.08.03.D | I116: 0
A117: 不可修件 | B117: Y2.PD.0209.LO | C117: 3M長期UV全透明彩繪PVC-月台滑門(右) | D117: X 工程廠商依契約提供之備品 | E117: 廠牌：爵士影像事業有限公司 規格：103cm*208cm 說明:月台滑門(右) | F117: PC | G117: 環狀線南機廠空調倉庫 | H117: YSAC1.08.03.D | I117: 0
A118: 工具/儀器 | B118: 95.01.0108.KT | C118: 14x18更換式扭力扳手接頭 (開口型) | D118: N 採購品 | E118: 品牌型號KING TONY 34501226M 規格： 1.長度：69mm(±20mm) 2.扭力範圍：359(牛頓-米) | F118: PC | G118: 淡海輕軌中心倉庫 | H118: DMS8888 | I118: 3
A119: 不可修件 | B119: 39.17.0024.TP | C119: 安全切換開關 | D119: X 工程廠商依契約提供之備品 | E119: 電控適用 | F119: PC | G119: 淡海輕軌中心倉庫 | H119: DMW1321 | I119: 1
A120: 不可修件 | B120: 39.17.0024.TP | C120: 安全切換開關 | D120: X 工程廠商依契約提供之備品 | E120: 電控適用 | F120: PC | G120: 安坑輕軌中心倉庫 | H120: AMW1721 | I120: 1
A121: 不可修件 | B121: Y8.BA.0004.OT | C121: 後乘場門門板(無機房1000kg) | D121: X 工程廠商依契約提供之備品 | E121: 1.廠牌：OTIS。2.型號：Rear Outer door T-T 900。3.用途：適用環狀線OTIS電梯。4.規格：(1)含左、右門板。(2)材質：304髮紋不銹鋼。(3)厚度：1.5mm±0.1mm。 | F121: EA | G121: 環狀線南機廠大型物料倉庫 | H121: YSD.02.02.B.02 | I121: 1
A122: 不可修件 | B122: Y5.14.0023.LO | C122: 乙太網路介面卡 | D122: X 工程廠商依契約提供之備品 | E122: 1.廠牌：阿爾卡特朗訊ALCATEL-LUCENT 2.型號：3AL81915BA 3.用途：FOT替換性備品 | F122: EA | G122: 環狀線南機廠空調倉庫 | H122: YSAC1.03.07.D | I122: 0
A123: 可修件 | B123: 32.AP.0005.BB | C123: BPI界面轉換器 | D123: X 工程廠商依契約提供之備品 | E123: 一、廠牌: BBR 二、型號: PZB-226 BPI 三、規格: 處理器AMD geode LX800、快閃儲存器8 G、工作記憶體128M RAM | F123: PC | G123: 淡海輕軌中心倉庫 | H123: DMW3311 | I123: 0
A124: 可修件 | B124: 32.AP.0005.BB | C124: BPI界面轉換器 | D124: X 工程廠商依契約提供之備品 | E124: 一、廠牌: BBR 二、型號: PZB-226 BPI 三、規格: 處理器AMD geode LX800、快閃儲存器8 G、工作記憶體128M RAM | F124: PC | G124: 淡海輕軌中心倉庫 | H124: DMW3311 | I124: 0
A125: 可修件 | B125: 32.AP.0005.BB | C125: BPI界面轉換器 | D125: X 工程廠商依契約提供之備品 | E125: 一、廠牌: BBR 二、型號: PZB-226 BPI 三、規格: 處理器AMD geode LX800、快閃儲存器8 G、工作記憶體128M RAM | F125: PC | G125: 安坑輕軌分存站 | H125: ATS0002 | I125: 1
A126: 代管捷運局之工具/儀器 | B126: 95.01.0012.KW | C126: 梅開扳手(10 mm) | D126: X 工程廠商依契約提供之備品 | E126: 梅開扳手(10 mm) | F126: PC | G126: 淡海輕軌中心倉庫 | H126: DMW1311 | I126: 20
... A131: 不可修件 | B131: 35.28.0007.AV | C131: IP電話機 | D131: X 工程廠商依契約提供之備品 | E131: TEL電話系統使用 | F131: PC | G131: 淡海輕軌中心倉庫 | H131: DMW3112 | I131: 10
A132: 時限品 | B132: YA.II.0008.LO | C132: 傳動皮帶(SPZ-1180) | D132: X 工程廠商依契約提供之備品 | E132: 廠牌:Continental型號:SPZ-1180*2條產品標示之保存期限：自製造日起至少 60 個月 | F132: ST | G132: 環狀線南機廠主倉庫 | H132: YSC.03.14.B.01.03.03.T | I132: 0 | J132: 2024/02/01
A133: 不可修件 | B133: Y3.DC.0028.LO | C133: LED指示燈，紅色 | D133: X 工程廠商依契約提供之備品 | E133: 1.廠牌：DOMO 2.型號：HD22（Red) 3.環狀線專屬用料 | F133: PC | G133: 環狀線南機廠空調倉庫 | H133: YSAC1.01.03.B.02 | I133: 3
A134: 不可修件 | B134: Y9.P4.0003.CF | C134: PAM印表機變壓器 | D134: X 工程廠商依契約提供之備品 | E134: 廠牌:EPSON 型號:M235B 規格:輸出24V/1.5A | F134: EA | G134: 運務中心票務課現場料架-板橋Y15 | H134: YSKF.02.03.C | I134: 1
A135: 不可修件 | B135: Y9.P4.0003.CF | C135: PAM印表機變壓器 | D135: X 工程廠商依契約提供之備品 | E135: 廠牌:EPSON 型號:M235B 規格:輸出24V/1.5A | F135: EA | G135: 環狀線南機廠空調倉庫 | H135: YSAC1.04.03.F.01 | I135: 0
A136: 時限品 | B136: YC.A1.0054.LR | C136: 液壓油 | D136: X 工程廠商依契約提供之備品 | E136: 料號 : 76192-1 AVIA Syntofluid PE-B 32L 規格:20公升 | F136: PL | G136: 環狀線南機廠特殊品倉庫 | H136: YSK.03.01.D.01.02.T | I136: 0 | J136: 2032/01/14
A137: 時限品 | B137: YC.A1.0054.LR | C137: 液壓油 | D137: X 工程廠商依契約提供之備品 | E137: 料號 : 76192-1 AVIA Syntofluid PE-B 32L 規格:20公升 | F137: PL | G137: 環狀線南機廠特殊品倉庫 | H137: YSK.03.02.C.01.01.T2 | I137: 1 | J137: 2032/01/14
A138: 不可修件 | B138: 48.FF.0070.KU | C138: 燈具L5 | D138: X 工程廠商依契約提供之備品 | E138: 1.廠牌:凱優牌 2.型號:L5 3.規格:LED崁燈42W/4300流明 | F138: EA | G138: 安坑輕軌分存站 | H138: ATS0004 | I138: 3
A139: 不可修件 | B139: 94.20.0028.YS | C139: 絕緣毯 | D139: N 採購品 | E139: 1.耐電壓：20kV 2.材質：橡膠 3.使用電壓：17kV | F139: ST | G139: 淡海輕軌中心倉庫 | H139: DMS0000 | I139: 1
...

Sheet 請購點公式
A1: 請購點（Reorder Point, ROP）模板
A3: 這份模板將依下式自動計算請購點：
A4: ROP = d × T + Z × σd × √T
A5: 其中：
A6: d = 年使用量U / 年天數W（可用365或工作天數250）
A7: T = 交貨期 (L)+ 採購前置時間(P)
A8: Z：由安全等級(1~4)對應的服務水準Z值（見「參數」頁）
A9: σd = 0.25 × d（CV為需求變異係數，可在「參數」頁設定預設值）
A11: C = 是否為市售之指示（市售=0、非市售=1）
A12: 若交期 L > 門檻：視為非市售 (C=1)，啟動風險係數 r。
A13: 若交期 L <門檻：視為市售 (C=0)。
A14: 門檻初始設計60天
... A16: 3) 系統將自動計算日需求、有效等待時間T、安全庫存、請購點(ROP)。

Sheet 參數
A1: 項目 | B1: 值 | D1: 安全等級 | E1: 服務水準(%) | F1: Z值
A2: 年天數 W（天） | B2: 365 | D2: 1 | E2: 90 | F2: 1.28
A3: 非市售風險係數 r | B3: 0.3 | D3: 2 | E3: 95 | F3: 1.65
A4: 預設需求變異係數 CV | B4: 0.25 | D4: 3 | E4: 97.5 | F4: 1.96
D5: 4 | E5: 99 | F5: 2.33

Sheet 請購點計算
A1: 料號/品名 | B1: 年使用量 U(件/年) | C1: 年天數 W(天) | D1: 日需求 d(件/天) | E1: 交貨期 L(天) | F1: 採購前置時間 P(天) | G1: 安全等級 SL(1~4) | H1: Z值 | I1: 市售/非市售 | J1: 非市售風險係數 r | K1: 非市售指示 C | L1: 需求變異係數 CV | M1: 日需求標準差 σd | N1: 有效等待時間 T(天) | O1: 安全庫存 SS | P1: 請購點 ROP(件)
A2: =整合資料!$B$2 -> 電動起子馬達碳刷/廠牌：BOSCH，型號：2609199169 | B2: =整合資料!$AI$2 -> 2 | C2: =參數!$B$2 -> 365 | D2: =IFERROR(B2/C2,0) -> 0.0054794521 | E2: =整合資料!$AO$2 -> 0 | F2: =整合資料!$AP$2 -> 30 | G2: =整合資料!$AQ$2 -> 2 | H2: =IFERROR(VLOOKUP(G2,SL_Z_Table,3,FALSE),0) -> 1.645 | I2: =IF(E2>60,"非市售","市售") -> 市售 | J2: =參數!$B$3 -> 0.3 | K2: =IF(I2="非市售",1,0) -> 0 | L2: =參數!$B$4 -> 0.25 | M2: =L2*D2 -> 0.001369863 | N2: =E2*(1+J2*K2)+F2 -> 30 | O2: =H2*M2*SQRT(N2) -> 0.012342515 | P2: =ROUNDUP(D2*N2+O2,0) -> 1
A3: =整合資料!$B$3 -> 油漆筆(白)/白色 | B3: =整合資料!$AI$3 -> 33 | C3: =參數!$B$2 -> 365 | D3: =IFERROR(B3/C3,0) -> 0.090410959 | E3: =整合資料!$AO$3 -> 0 | F3: =整合資料!$AP$3 -> 30 | G3: =整合資料!$AQ$3 -> 3 | H3: =IFERROR(VLOOKUP(G3,SL_Z_Table,3,FALSE),0) -> 1.96 | I3: =IF(E3>60,"非市售","市售") -> 市售 | J3: =參數!$B$3 -> 0.3 | K3: =IF(I3="非市售",1,0) -> 0 | L3: =參數!$B$4 -> 0.25 | M3: =L3*D3 -> 0.02260274 | N3: =E3*(1+J3*K3)+F3 -> 30 | O3: =H3*M3*SQRT(N3) -> 0.2426486

Sheet 工作表1
A1: 交貨期(L) | BA1: 料號/品名 | BB1: 年使用量 U(件/年) | BC1: 年天數 W(天) | BD1: 日需求 d(件/天) | BE1: 交貨期 L(天) | BF1: 採購前置時間 P(天) | BG1: 安全等級 SL(1~5) | BH1: Z值 | BI1: 市售/非市售 | BJ1: 非市售風險係數 r | BK1: 非市售指示 C | BL1: 需求變異係數 CV | BM1: 日需求標準差 σd | BN1: 有效等待時間 T(天) | BO1: 安全庫存 SS
A2: 0 | B2: =_xlfn.IFS(A2=0, "0(無資料)", A2<=30, "1~30", A2<=60, "31~60", A2<=90, "61~90", A2<=120, "91~120", A2<=150, "121~150", A2<=180, "151~180", A2<=240, "181~240", A2<=330, "241~330", A2>330, "360以上") -> 0(無資料) | E2: 交貨天數下限 (欄位 E) | F2: 群組名稱 (欄位 F) | BA2: =整合資料!B2 -> 電動起子馬達碳刷/廠牌：BOSCH，型號：2609199169 | BB2: =整合資料!AK2 -> 0 | BC2: =[0]!W -> 365 | BD2: =IFERROR(BB2/BC2,0) -> 0 | BE2: =整合資料!AO2 -> 0 | BF2: =整合資料!AP2 -> 30 | BG2: =整合資料!AQ2 -> 2 | BH2: =IFERROR(VLOOKUP(BG2,SL_Z_Table,3,FALSE),0) -> 1.645 | BI2: =IF(整合資料!AO2>60,"非市售","市售") -> 市售 | BJ2: =參數!$B$3 -> 0.3 | BK2: =IF(BI2="非市售",1,0) -> 0 | BL2: =參數!$B$4 -> 0.25 | BM2: =BL2*BD2 -> 0 | BN2: =BE2*(1+BJ2*BK2)+BF2 -> 30 | BO2: =BH2*BM2*SQRT(BN2) -> 0
A3: 0 | E3: 0 | F3: 0(無資料) | BA3: =整合資料!B3 -> 油漆筆(白)/白色 | BB3: =整合資料!AK3 -> 10 | BC3: =[0]!W -> 365 | BD3: =IFERROR(BB3/BC3,0) -> 0.02739726 | BE3: =整合資料!AO3 -> 0 | BF3: =整合資料!AP3 -> 30 | BG3: =整合資料!AQ3 -> 3 | BH3: =IFERROR(VLOOKUP(BG3,SL_Z_Table,3,FALSE),0) -> 1.96 | BI3: =IF(整合資料!AO3>60,"非市售","市售") -> 市售 | BJ3: =參數!$B$3 -> 0.3 | BK3: =IF(BI3="非市售",1,0) -> 0 | BL3: =參數!$B$4 -> 0.25 | BM3: =BL3*BD3 -> 0.0068493151 | BN3: =BE3*(1+BJ3*BK3)+BF3 -> 30 | BO3: =BH3*BM3*SQRT(BN3) -> 0.073529878
A4: 0 | E4: 1 | F4: 1~30 | BA4: =整合資料!B4 -> 油漆筆(黃)/黃色 | BB4: =整合資料!AK4 -> 0 | BC4: =[0]!W -> 365 | BD4: =IFERROR(BB4/BC4,0) -> 0 | BE4: =整合資料!AO4 -> 0 | BF4: =整合資料!AP4 -> 30 | BG4: =整合資料!AQ4 -> 3 | BH4: =IFERROR(VLOOKUP(BG4,SL_Z_Table,3,FALSE),0) -> 1.96 | BI4: =IF(整合資料!AO4>60,"非市售","市售") -> 市售 | BJ4: =參數!$B$3 -> 0.3 | BK4: =IF(BI4="非市售",1,0) -> 0 | BL4: =參數!$B$4 -> 0.25 | BM4: =BL4*BD4 -> 0 | BN4: =BE4*(1+BJ4*BK4)+BF4 -> 30 | BO4: =BH4*BM4*SQRT(BN4) -> 0
A5: 0 | E5: 31 | F5: 31~60 | BA5: =整合資料!B5 -> 噴漆(白)/1.顏色: 白色 2.容量:400ml/罐(含)以上/CN | BB5: =整合資料!AK5 -> 0 | BC5: =[0]!W -> 365 | BD5: =IFERROR(BB5/BC5,0) -> 0 | BE5: =整合資料!AO5 -> 0 | BF5: =整合資料!AP5 -> 30 | BG5: =整合資料!AQ5 -> 3 | BH5: =IFERROR(VLOOKUP(BG5,SL_Z_Table,3,FALSE),0) -> 1.96 | BI5: =IF(整合資料!AO5>60,"非市售","市售") -> 市售 | BJ5: =參數!$B$3 -> 0.3 | BK5: =IF(BI5="非市售",1,0) -> 0 | BL5: =參數!$B$4 -> 0.25 | BM5: =BL5*BD5 -> 0 | BN5: =BE5*(1+BJ5*BK5)+BF5 -> 30 | BO5: =BH5*BM5*SQRT(BN5) -> 0
A6: 0 | E6: 61 | F6: 61~90 | BA6: =整合資料!B6 -> 噴漆(黑)/1.顏色: 黑色 2.容量:400ml/罐(含)以上/CN | BB6: =整合資料!AK6 -> 0 | BC6: =[0]!W -> 365 | BD6: =IFERROR(BB6/BC6,0) -> 0 | BE6: =整合資料!AO6 -> 0 | BF6: =整合資料!AP6 -> 30 | BG6: =整合資料!AQ6 -> 3 | BH6: =IFERROR(VLOOKUP(BG6,SL_Z_Table,3,FALSE),0) -> 1.96 | BI6: =IF(整合資料!AO6>60,"非市售","市售") -> 市售 | BJ6: =參數!$B$3 -> 0.3 | BK6: =IF(BI6="非市售",1,0) -> 0 | BL6: =參數!$B$4 -> 0.25 | BM6: =BL6*BD6 -> 0 | BN6: =BE6*(1+BJ6*BK6)+BF6 -> 30 | BO6: =BH6*BM6*SQRT(BN6) -> 0
A7: 0 | E7: 91 | F7: 91~120 | BA7: =整合資料!B7 -> 冷鍍鋅漆/13oz/CN，噴霧式，產品標示之保存期限：自製造日起至少 36 個月 | BB7: =整合資料!AK7 -> 2 | BC7: =[0]!W -> 365 | BD7: =IFERROR(BB7/BC7,0) -> 0.0054794521 | BE7: =整合資料!AO7 -> 0 | BF7: =整合資料!AP7 -> 30 | BG7: =整合資料!AQ7 -> 2 | BH7: =IFERROR(VLOOKUP(BG7,SL_Z_Table,3,FALSE),0) -> 1.645 | BI7: =IF(整合資料!AO7>60,"非市售","市售") -> 市售 | BJ7: =參數!$B$3 -> 0.3 | BK7: =IF(BI7="非市售",1,0) -> 0 | BL7: =參數!$B$4 -> 0.25 | BM7: =BL7*BD7 -> 0.001369863 | BN7: =BE7*(1+BJ7*BK7)+BF7 -> 30 | BO7: =BH7*BM7*SQRT(BN7) -> 0.012342515
A8: 0 | E8: 121 | F8: 121~150 | BA8: =整合資料!B8 -> 蒸餾水/1.適用電瓶加水用，不含金屬導電物 2.包裝方式：5GAL/桶 | BB8: =整合資料!AK8 -> 21 | BC8: =[0]!W -> 365 | BD8: =IFERROR(BB8/BC8,0) -> 0.057534247 | BE8: =整合資料!AO8 -> 0 | BF8: =整合資料!AP8 -> 30 | BG8: =整合資料!AQ8 -> 2 | BH8: =IFERROR(VLOOKUP(BG8,SL_Z_Table,3,FALSE),0) -> 1.645 | BI8: =IF(整合資料!AO8>60,"非市售","市售") -> 市售 | BJ8: =參數!$B$3 -> 0.3 | BK8: =IF(BI8="非市售",1,0) -> 0 | BL8: =參數!$B$4 -> 0.25 | BM8: =BL8*BD8 -> 0.014383562 | BN8: =BE8*(1+BJ8*BK8)+BF8 -> 30 | BO8: =BH8*BM8*SQRT(BN8) -> 0.12959641
A9: 0 | E9: 151 | F9: 151~180 | BA9: =整合資料!B9 -> 木柄銅絲刷/植毛寬度:20mm±3mm，植毛長度:75mm±5mm，毛長:15mm±3mm，總長220mm以上 | BB9: =整合資料!AK9 -> 20 | BC9: =[0]!W -> 365 | BD9: =IFERROR(BB9/BC9,0) -> 0.054794521 | BE9: =整合資料!AO9 -> 0 | BF9: =整合資料!AP9 -> 30 | BG9: =整合資料!AQ9 -> 2 | BH9: =IFERROR(VLOOKUP(BG9,SL_Z_Table,3,FALSE),0) -> 1.645 | BI9: =IF(整合資料!AO9>60,"非市售","市售") -> 市售 | BJ9: =參數!$B$3 -> 0.3 | BK9: =IF(BI9="非市售",1,0) -> 0 | BL9: =參數!$B$4 -> 0.25 | BM9: =BL9*BD9 -> 0.01369863 | BN9: =BE9*(1+BJ9*BK9)+BF9 -> 30 | BO9: =BH9*BM9*SQRT(BN9) -> 0.12342515
A10: 0 | E10: 181 | F10: 181~240 | BA10: =整合資料!B10 -> 氬氣/充填壓力120kg/c㎡以上，容積6立方米 | BB10: =整合資料!AK10 -> 0 | BC10: =[0]!W -> 365 | BD10: =IFERROR(BB10/BC10,0) -> 0 | BE10: =整合資料!AO10 -> 0 | BF10: =整合資料!AP10 -> 30 | BG10: =整合資料!AQ10 -> 2 | BH10: =IFERROR(VLOOKUP(BG10,SL_Z_Table,3,FALSE),0) -> 1.645 | BI10: =IF(整合資料!AO10>60,"非市售","市售") -> 市售 | BJ10: =參數!$B$3 -> 0.3 | BK10: =IF(BI10="非市售",1,0) -> 0 | BL10: =參數!$B$4 -> 0.25 | BM10: =BL10*BD10 -> 0 | BN10: =BE10*(1+BJ10*BK10)+BF10 -> 30 | BO10: =BH10*BM10*SQRT(BN10) -> 0
A11: 0 | E11: 241 | F11: 241~330 | BA11: =整合資料!B11 -> 氮氣(含瓶身)/1.充填壓力：190kg/c㎡以上，水容積：50L，容積：10立方米。 2.適用氣體名稱：氮氣。 3.接頭型式：CGA580。 4.須含鋼瓶身。 | BB11: =整合資料!AK11 -> 9 | BC11: =[0]!W -> 365 | BD11: =IFERROR(BB11/BC11,0) -> 0.024657534 | BE11: =整合資料!AO11 -> 0 | BF11: =整合資料!AP11 -> 30 | BG11: =整合資料!AQ11 -> 2 | BH11: =IFERROR(VLOOKUP(BG11,SL_Z_Table,3,FALSE),0) -> 1.645 | BI11: =IF(整合資料!AO11>60,"非市售","市售") -> 市售 | BJ11: =參數!$B$3 -> 0.3 | BK11: =IF(BI11="非市售",1,0) -> 0 | BL11: =參數!$B$4 -> 0.25 | BM11: =BL11*BD11 -> 0.0061643836 | BN11: =BE11*(1+BJ11*BK11)+BF11 -> 30 | BO11: =BH11*BM11*SQRT(BN11) -> 0.055541318
A12: 0 | E12: 331 | F12: 360以上 | BA12: =整合資料!B12 -> PVC絕緣膠布(紅色)/紅色 0.2mm*19mm*10m | BB12: =整合資料!AK12 -> 5 | BC12: =[0]!W -> 365 | BD12: =IFERROR(BB12/BC12,0) -> 0.01369863 | BE12: =整合資料!AO12 -> 0 | BF12: =整合資料!AP12 -> 30 | BG12: =整合資料!AQ12 -> 2 | BH12: =IFERROR(VLOOKUP(BG12,SL_Z_Table,3,FALSE),0) -> 1.645 | BI12: =IF(整合資料!AO12>60,"非市售","市售") -> 市售 | BJ12: =參數!$B$3 -> 0.3 | BK12: =IF(BI12="非市售",1,0) -> 0 | BL12: =參數!$B$4 -> 0.25 | BM12: =BL12*BD12 -> 0.0034246575 | BN12: =BE12*(1+BJ12*BK12)+BF12 -> 30 | BO12: =BH12*BM12*SQRT(BN12) -> 0.030856288
A13: 0 | BA13: =整合資料!B13 -> PVC絕緣膠布(黑色)/黑色 0.2mm*19mm 10m | BB13: =整合資料!AK13 -> 9 | BC13: =[0]!W -> 365 | BD13: =IFERROR(BB13/BC13,0) -> 0.024657534 | BE13: =整合資料!AO13 -> 0 | BF13: =整合資料!AP13 -> 30 | BG13: =整合資料!AQ13 -> 2 | BH13: =IFERROR(VLOOKUP(BG13,SL_Z_Table,3,FALSE),0) -> 1.645 | BI13: =IF(整合資料!AO13>60,"非市售","市售") -> 市售 | BJ13: =參數!$B$3 -> 0.3 | BK13: =IF(BI13="非市售",1,0) -> 0 | BL13: =參數!$B$4 -> 0.25 | BM13: =BL13*BD13 -> 0.0061643836 | BN13: =BE13*(1+BJ13*BK13)+BF13 -> 30 | BO13: =BH13*BM13*SQRT(BN13) -> 0.055541318
A14: 0 | BA14: =整合資料!B14 -> PVC絕緣膠布(黃色)/黃色 0.2mm*19mm*10m | BB14: =整合資料!AK14 -> 1 | BC14: =[0]!W -> 365 | BD14: =IFERROR(BB14/BC14,0) -> 0.002739726 | BE14: =整合資料!AO14 -> 0 | BF14: =整合資料!AP14 -> 30 | BG14: =整合資料!AQ14 -> 2 | BH14: =IFERROR(VLOOKUP(BG14,SL_Z_Table,3,FALSE),0) -> 1.645 | BI14: =IF(整合資料!AO14>60,"非市售","市售") -> 市售 | BJ14: =參數!$B$3 -> 0.3 | BK14: =IF(BI14="非市售",1,0) -> 0 | BL14: =參數!$B$4 -> 0.25 | BM14: =BL14*BD14 -> 0.00068493151 | BN14: =BE14*(1+BJ14*BK14)+BF14 -> 30 | BO14: =BH14*BM14*SQRT(BN14) -> 0.0061712576
A15: 0 | BA15: =整合資料!B15 -> PVC絕緣膠布(白色)/白色 0.2mm*19mm*10m | BB15: =整合資料!AK15 -> 4 | BC15: =[0]!W -> 365 | BD15: =IFERROR(BB15/BC15,0) -> 0.010958904 | BE15: =整合資料!AO15 -> 0 | BF15: =整合資料!AP15 -> 30 | BG15: =整合資料!AQ15 -> 2 | BH15: =IFERROR(VLOOKUP(BG15,SL_Z_Table,3,FALSE),0) -> 1.645 | BI15: =IF(整合資料!AO15>60,"非市售","市售") -> 市售 | BJ15: =參數!$B$3 -> 0.3 | BK15: =IF(BI15="非市售",1,0) -> 0 | BL15: =參數!$B$4 -> 0.25 | BM15: =BL15*BD15 -> 0.002739726 | BN15: =BE15*(1+BJ15*BK15)+BF15 -> 30 | BO15: =BH15*BM15*SQRT(BN15) -> 0.02468503
A16: 0 | BA16: =整合資料!B16 -> PVC絕緣膠布(綠色)/綠色 0.2mm*19mm*10m | BB16: =整合資料!AK16 -> 2 | BC16: =[0]!W -> 365 | BD16: =IFERROR(BB16/BC16,0) -> 0.0054794521 | BE16: =整合資料!AO16 -> 0 | BF16: =整合資料!AP16 -> 30 | BG16: =整合資料!AQ16 -> 2 | BH16: =IFERROR(VLOOKUP(BG16,SL_Z_Table,3,FALSE),0) -> 1.645 | BI16: =IF(整合資料!AO16>60,"非市售","市售") -> 市售 | BJ16: =參數!$B$3 -> 0.3 | BK16: =IF(BI16="非市售",1,0) -> 0 | BL16: =參數!$B$4 -> 0.25 | BM16: =BL16*BD16 -> 0.001369863 | BN16: =BE16*(1+BJ16*BK16)+BF16 -> 30 | BO16: =BH16*BM16*SQRT(BN16) -> 0.012342515
A17: 0 | BA17: =整合資料!B17 -> 止洩帶/一般管路防漏用，規格：厚度：0.1mm、寬度：13mm、每捲長度：15m以上 | BB17: =整合資料!AK17 -> 16 | BC17: =[0]!W -> 365 | BD17: =IFERROR(BB17/BC17,0) -> 0.043835616 | BE17: =整合資料!AO17 -> 0 | BF17: =整合資料!AP17 -> 30 | BG17: =整合資料!AQ17 -> 2 | BH17: =IFERROR(VLOOKUP(BG17,SL_Z_Table,3,FALSE),0) -> 1.645 | BI17: =IF(整合資料!AO17>60,"非市售","市售") -> 市售 | BJ17: =參數!$B$3 -> 0.3 | BK17: =IF(BI17="非市售",1,0) -> 0 | BL17: =參數!$B$4 -> 0.25 | BM17: =BL17*BD17 -> 0.010958904 | BN17: =BE17*(1+BJ17*BK17)+BF17 -> 30 | BO17: =BH17*BM17*SQRT(BN17) -> 0.098740121
A18: 0 | BA18: =整合資料!B18 -> 矽利康(施敏打硬，黑)/1、廠牌：CEMEDINE ，型號：SUPER X NO.8008，容量:333ml/條，顏色：黑。 2、保存期限：自製造日起至少12個月。 | BB18: =整合資料!AK18 -> 1 | BC18: =[0]!W -> 365 | BD18: =IFERROR(BB18/BC18,0) -> 0.002739726 | BE18: =整合資料!AO18 -> 0 | BF18: =整合資料!AP18 -> 30 | BG18: =整合資料!AQ18 -> 2 | BH18: =IFERROR(VLOOKUP(BG18,SL_Z_Table,3,FALSE),0) -> 1.645 | BI18: =IF(整合資料!AO18>60,"非市售","市售") -> 市售 | BJ18: =參數!$B$3 -> 0.3 | BK18: =IF(BI18="非市售",1,0) -> 0 | BL18: =參數!$B$4 -> 0.25 | BM18: =BL18*BD18 -> 0.00068493151 | BN18: =BE18*(1+BJ18*BK18)+BF18 -> 30 | BO18: =BH18*BM18*SQRT(BN18) -> 0.0061712576
A19: 0 | BA19: =整合資料!B19 -> 熱縮套管(10.4mm)/1、廠牌：KSS，型號：F32-10 。 2、尺寸：收縮前內徑10.4mm±0.4mm。 3、內徑收縮率50%以上。 4、顏色：黑色。 5、包裝：50m/捲。 | BB19: =整合資料!AK19 -> 2 | BC19: =[0]!W -> 365 | BD19: =IFERROR(BB19/BC19,0) -> 0.0054794521 | BE19: =整合資料!AO19 -> 0 | BF19: =整合資料!AP19 -> 30 | BG19: =整合資料!AQ19 -> 2 | BH19: =IFERROR(VLOOKUP(BG19,SL_Z_Table,3,FALSE),0) -> 1.645 | BI19: =IF(整合資料!AO19>60,"非市售","市售") -> 市售 | BJ19: =參數!$B$3 -> 0.3 | BK19: =IF(BI19="非市售",1,0) -> 0 | BL19: =參數!$B$4 -> 0.25 | BM19: =BL19*BD19 -> 0.001369863 | BN19: =BE19*(1+BJ19*BK19)+BF19 -> 30 | BO19: =BH19*BM19*SQRT(BN19) -> 0.012342515
A20: 0 | BA20: =整合資料!B20 -> 熱縮套管(3.5mm)/1、廠牌：KSS，型號：F32-3。 2、尺寸：收縮前內徑3.5mm±0.3mm。 3、內徑收縮率50%以上。 4、顏色：黑色。 5、包裝：200m/捲。 | BB20: =整合資料!AK20 -> 2 | BC20: =[0]!W -> 365 | BD20: =IFERROR(BB20/BC20,0) -> 0.0054794521 | BE20: =整合資料!AO20 -> 0 | BF20: =整合資料!AP20 -> 30 | BG20: =整合資料!AQ20 -> 2 | BH20: =IFERROR(VLOOKUP(BG20,SL_Z_Table,3,FALSE),0) -> 1.645 | BI20: =IF(整合資料!AO20>60,"非市售","市售") -> 市售 | BJ20: =參數!$B$3 -> 0.3 | BK20: =IF(BI20="非市售",1,0) -> 0 | BL20: =參數!$B$4 -> 0.25 | BM20: =BL20*BD20 -> 0.001369863 | BN20: =BE20*(1+BJ20*BK20)+BF20 -> 30 | BO20: =BH20*BM20*SQRT(BN20) -> 0.012342515
A21: 0 | BA21: =整合資料!B21 -> PVC絕緣膠布(藍色)/藍色 0.2mm*19mm*10m。 | BB21: =整合資料!AK21 -> 2 | BC21: =[0]!W -> 365 | BD21: =IFERROR(BB21/BC21,0) -> 0.0054794521 | BE21: =整合資料!AO21 -> 0 | BF21: =整合資料!AP21 -> 30 | BG21: =整合資料!AQ21 -> 2 | BH21: =IFERROR(VLOOKUP(BG21,SL_Z_Table,3,FALSE),0) -> 1.645 | BI21: =IF(整合資料!AO21>60,"非市售","市售") -> 市售 | BJ21: =參數!$B$3 -> 0.3 | BK21: =IF(BI21="非市售",1,0) -> 0 | BL21: =參數!$B$4 -> 0.25 | BM21: =BL21*BD21 -> 0.001369863 | BN21: =BE21*(1+BJ21*BK21)+BF21 -> 30 | BO21: =BH21*BM21*SQRT(BN21) -> 0.012342515
A22: 0 | BA22: =整合資料!B22 -> 凡士林(潤滑用)/容量:1kg/瓶 | BB22: =整合資料!AK22 -> 0 | BC22: =[0]!W -> 365 | BD22: =IFERROR(BB22/BC22,0) -> 0 | BE22: =整合資料!AO22 -> 0 | BF22: =整合資料!AP22 -> 30 | BG22: =整合資料!AQ22 -> 2 | BH22: =IFERROR(VLOOKUP(BG22,SL_Z_Table,3,FALSE),0) -> 1.645 | BI22: =IF(整合資料!AO22>60,"非市售","市售") -> 市售 | BJ22: =參數!$B$3 -> 0.3 | BK22: =IF(BI22="非市售",1,0) -> 0 | BL22: =參數!$B$4 -> 0.25 | BM22: =BL22*BD22 -> 0 | BN22: =BE22*(1+BJ22*BK22)+BF22 -> 30 | BO22: =BH22*BM22*SQRT(BN22) -> 0
A23: 0 | BA23: =整合資料!B23 -> 液壓油(SHELL TELLUS S2 MX 46)/1.廠牌：SHELL、型號：TELLUS S2 MX 46。2.包裝方式：209公升/桶。3.產品標示之保存期限：自製造日起至少48 個月。 | BB23: =整合資料!AK23 -> 5 | BC23: =[0]!W -> 365 | BD23: =IFERROR(BB23/BC23,0) -> 0.01369863 | BE23: =整合資料!AO23 -> 0 | BF23: =整合資料!AP23 -> 30 | BG23: =整合資料!AQ23 -> 2 | BH23: =IFERROR(VLOOKUP(BG23,SL_Z_Table,3,FALSE),0) -> 1.645 | BI23: =IF(整合資料!AO23>60,"非市售","市售") -> 市售 | BJ23: =參數!$B$3 -> 0.3 | BK23: =IF(BI23="非市售",1,0) -> 0 | BL23: =參數!$B$4 -> 0.25 | BM23: =BL23*BD23 -> 0.0034246575 | BN23: =BE23*(1+BJ23*BK23)+BF23 -> 30 | BO23: =BH23*BM23*SQRT(BN23) -> 0.030856288
A24: 0 | BA24: =整合資料!B24 -> 除銹潤滑油/具有滲透除銹、潤滑鎖頭、消除因機械磨擦產生雜聲等功能，可作為各類金屬或一般材質零組件的維修保養使用，包裝方式：380ml以上，產品標示之保存期限：自製造日起至少 24 個月 | BB24: =整合資料!AK24 -> 15 | BC24: =[0]!W -> 365 | BD24: =IFERROR(BB24/BC24,0) -> 0.04109589 | BE24: =整合資料!AO24 -> 0 | BF24: =整合資料!AP24 -> 30 | BG24: =整合資料!AQ24 -> 2 | BH24: =IFERROR(VLOOKUP(BG24,SL_Z_Table,3,FALSE),0) -> 1.645 | BI24: =IF(整合資料!AO24>60,"非市售","市售") -> 市售 | BJ24: =參數!$B$3 -> 0.3 | BK24: =IF(BI24="非市售",1,0) -> 0 | BL24: =參數!$B$4 -> 0.25 | BM24: =BL24*BD24 -> 0.010273973 | BN24: =BE24*(1+BJ24*BK24)+BF24 -> 30 | BO24: =BH24*BM24*SQRT(BN24) -> 0.092568864
... A259: 0 | BA259: =整合資料!B259 -> 導熱膏(DC340)/廠牌：DOWSIL或同等品，型號：DC340，容量：142g/條。 | BB259: =整合資料!AK259 -> 3 | BC259: =[0]!W -> 365 | BD259: =IFERROR(BB259/BC259,0) -> 0.0082191781 | BE259: =整合資料!AO259 -> 0 | BF259: =整合資料!AP259 -> 30 | BG259: =整合資料!AQ259 -> 2 | BH259: =IFERROR(VLOOKUP(BG259,SL_Z_Table,3,FALSE),0) -> 1.645 | BI259: =IF(整合資料!AO259>60,"非市售","市售") -> 市售 | BJ259: =參數!$B$3 -> 0.3 | BK259: =IF(BI259="非市售",1,0) -> 0 | BL259: =參數!$B$4 -> 0.25 | BM259: =BL259*BD259 -> 0.0020547945 | BN259: =BE259*(1+BJ259*BK259)+BF259 -> 30 | BO259: =BH259*BM259*SQRT(BN259) -> 0.018513773
A260: 0
A261: 0
A262: 0
A263: 0
A264: 0
A265: 0
A266: 0
A267: 0
A268: 0
A269: 0
A270: 0
A271: 0
... A1300: 540
